Workbook

Sheet 📊 Use Case Value Register
A1: STATKRAFT PROCUREMENT AI — COMPREHENSIVE USE CASE VALUE REGISTER | Based on Qwen 35B Market Research + Internal Benchmarks
A3: Prepared: March 2026 | Research Sources: McKinsey, BCG, Hackett Group, Equinor, Zip, Coupa, Resilinc, Ironclad, Fairmarkit, Arkestro, SAP, Jaggaer | All EUR values based on €500M annual spend, 45 FTE, €120K FTE cost
A5: ⚙️ KEY INPUTS — Change yellow cells to reflect Statkraft actuals
A6: Input Parameter | B6: Value | C6: Unit | D6: Source
A7: Annual procurement spend (EUR) | B7: 500000000 | C7: EUR | D7: Statkraft estimate
A8: Procurement headcount (FTEs) | B8: 45 | C8: FTEs | D8: Statkraft internal
A9: Avg FTE fully-loaded cost (EUR/yr) | B9: 120000 | C9: EUR/yr | D9: Statkraft HR
A10: Sourcing events per year | B10: 250 | C10: events | D10: Statkraft estimate
A11: Avg hours per sourcing event (RFQ→award) | B11: 40 | C11: hrs | D11: Industry avg
A12: Active contracts in portfolio | B12: 1200 | C12: contracts | D12: Statkraft estimate
A13: Avg hours to manually review contract | B13: 4 | C13: hrs | D13: Luminance benchmark
A14: Suppliers actively monitored | B14: 200 | C14: count | D14: Statkraft target
A15: Annual manual supplier review cost | B15: 150000 | C15: EUR/yr | D15: Statkraft estimate
A16: Current spend classification accuracy | B16: 0.65 | C16: % | D16: Current state
A17: MRO/capex emergency premium (% of spend) | B17: 0.03 | C17: % | D17: Industry avg
A18: Avg hours to build negotiation pack | B18: 8 | C18: hrs | D18: Statkraft estimate
... A26: Supplier onboarding time (days) | B26: 45 | C26: days | D26: Statkraft estimate
A29: 💰 USE CASE VALUE ANALYSIS — All 20 Use Cases with Evidence-Based Benchmarks
A30: # | B30: Use Case | C30: Category | D30: Benchmark Source | E30: Benchmark %/Metric | F30: Calculation Method | G30: Bear (50% of base) | H30: Base Estimate | I30: Bull (150% of base) | J30: Confidence | K30: Evidence Quality | L30: Effort (weeks) | M30: Time to Value | N30: Track | O30: One-time Cost (EUR) | P30: Annual Cost (EUR) | Q30: Net Annual Value (EUR) | R30: 3yr NPV (EUR) | S30: ROI | T30: Notes / Assumptions
A31: 1 | B31: Spend Classification & Enrichment | C31: Data Quality | D31: McKinsey / Equinor (500M NOK automation) | E31: 5-10% spend recovery from better classification accuracy | F31: Spend × (target accuracy 88% - current 65%) × 5% recovery rate | G31: =B7*(0.88-B16)*0.025 | H31: =B7*(0.88-B16)*0.05 | I31: =B7*(0.88-B16)*0.075 | J31: High | K31: McKinsey confirmed, Equinor implemented | L31: 3 | M31: 4–6 wks | N31: B | O31: 0 | P31: 15000 | Q31: =H31-P31 | R31: =Q31*3-O31 | S31: =IF(O31+P31>0,H31/(O31+P31),"∞") | T31: Cleans data for all other AI use cases. Foundation use case. SAP Joule native.
A32: 2 | B32: Contract NLP Scanning & Review | C32: Contract Mgmt | D32: Luminance / Icertis benchmark — 31% already using AI | E32: 80% faster contract review; review 1,200 contracts/yr | F32: Hours saved × FTE cost ÷ 1750 working hrs per year | G32: =B9/1750*B13*B19*0.8*0.4 | H32: =B9/1750*B13*B19*0.8 | I32: =B9/1750*B13*B19*0.8*1.5 | J32: High | K32: Luminance/Icertis benchmarked, 31% adoption live | L32: 4 | M32: 6–8 wks | N32: B | O32: 5000 | P32: 8000 | Q32: =H32-P32 | R32: =Q32*3-O32 | S32: =IF(O32+P32>0,H32/(O32+P32),"∞") | T32: 80% faster = 3.2 hrs saved per contract review. 1,200 contracts × 3.2h = 3,840h saved.
A33: 3 | B33: Supplier Monitoring Agent (Top 50→200) | C33: Risk Mgmt | D33: Resilinc (Gartner Magic Quadrant Leader) / Shell | E33: 70% reduction in manual monitoring costs; early warning reduces incidents | F33: Manual monitoring cost reduction + incident prevention value | G33: =B15*0.7*0.5 | H33: =B15*0.7 | I33: =B15*0.7*1.5 | J33: High | K33: Shell/TotalEnergies live, Resilinc Gartner Leader | L33: 6 | M33: 8–10 wks | N33: D | O33: 10000 | P33: 25000 | Q33: =H33-P33 | R33: =Q33*3-O33 | S33: =IF(O33+P33>0,H33/(O33+P33),"∞") | T33: Continuous vs. annual review. Resilinc: real-time disruption monitoring, tariff screening, forced labor compliance.
A34: 4 | B34: RFQ & Tender Drafting Agent | C34: Sourcing | D34: Ørsted / BP — autonomous RFQ generation from spec | E34: 75% time reduction; 4–8h saved per event | F34: Hours saved per event × events/yr × FTE cost ÷ 1750 | G34: =B11*B10*0.75*B9/1750*0.4 | H34: =B11*B10*0.75*B9/1750 | I34: =B11*B10*0.75*B9/1750*1.5 | J34: High | K34: Ørsted and BP live, Fairmarkit: 10x events per FTE | L34: 5 | M34: 8–12 wks | N34: D | O34: 15000 | P34: 30000 | Q34: =H34-P34 | R34: =Q34*3-O34 | S34: =IF(O34+P34>0,H34/(O34+P34),"∞") | T34: 250 events × 30h saved × €68.57/hr = €514K base. Fairmarkit: $40K savings per buyer per week.
A35: 5 | B35: Demand Forecasting — MRO & Capex | C35: MRO/Supply | D35: Vattenfall (6–12m horizon) / McKinsey (35% inventory reduction) | E35: 50% reduction in emergency premium buys; 13% inventory reduction | F35: Emergency premium spend reduction + inventory carrying cost savings | G35: =B7*B17*0.5*0.4+B7*0.02*0.13*0.4 | H35: =B7*B17*0.5+B7*0.02*0.13 | I35: =B7*B17*0.5*1.5+B7*0.02*0.13*1.5 | J35: High | K35: Vattenfall live, McKinsey 35% inventory reduction confirmed | L35: 8 | M35: 12–16 wks | N35: D | O35: 20000 | P35: 40000 | Q35: =H35-P35 | R35: =Q35*3-O35 | S35: =IF(O35+P35>0,H35/(O35+P35),"∞") | T35: MRO emergency premium 3% of spend = €15M. 50% reduction = €7.5M. Inventory saving ~€1.3M additional.
A36: 6 | B36: Negotiation Intelligence & Prep | C36: Sourcing | D36: Arkestro (18.8% savings per $1M) / McKinsey should-cost 13% savings | E36: 0.3% additional savings from better-prepared negotiations | F36: Total spend × % additional savings from AI-assisted negotiation prep | G36: =B7*0.003*0.5 | H36: =B7*0.003 | I36: =B7*0.003*1.8 | J36: Medium | K36: Arkestro: 18.8% savings/event; McKinsey: 13% should-cost savings | L36: 5 | M36: 8–12 wks | N36: D | O36: 10000 | P36: 20000 | Q36: =H36-P36 | R36: =Q36*3-O36 | S36: =IF(O36+P36>0,H36/(O36+P36),"∞") | T36: Conservative: 0.3% of €500M = €1.5M. Arkestro achieving 18.8% per event on direct materials negotiated.
A37: 7 | B37: Category Strategy Agent | C37: Strategy | D37: McKinsey autonomous category agents 15–30% efficiency; BCG 15–45% cost reduction | E37: 0.5% spend savings from better category strategy coverage (3→12 strategies/yr) | F37: Spend × savings % enabled by broader category strategy coverage | G37: =B7*0.005*0.4 | H37: =B7*0.005 | I37: =B7*0.005*2 | J37: Medium | K37: McKinsey/BCG benchmarked; Statkraft currently 3 strategies/yr | L37: 8 | M37: 12–20 wks | N37: D | O37: 25000 | P37: 50000 | Q37: =H37-P37 | R37: =Q37*3-O37 | S37: =IF(O37+P37>0,H37/(O37+P37),"∞") | T37: Increase from 3 to 12 category strategies per year. Each strategy covers average 4% of spend. 0.5% savings rate.
A38: 8 | B38: CSRD & ESG Compliance Automation | C38: Compliance | D38: CSRD mandatory 2026; Resilinc forced labor / tariff screening live | E38: 80% reduction in manual compliance checking hours | F38: Manual compliance hours saved × FTE cost ÷ 1750 + penalty risk reduction | G38: =B9/1750*B8*B22*0.8*0.4 | H38: =B9/1750*B8*B22*0.8 | I38: =B9/1750*B8*B22*0.8*1.5 | J38: High | K38: CSRD mandatory, Resilinc agent live on Azure | L38: 5 | M38: 10–14 wks | N38: D | O38: 15000 | P38: 25000 | Q38: =H38-P38 | R38: =Q38*3-O38 | S38: =IF(O38+P38>0,H38/(O38+P38),"∞") | T38: 200 suppliers × 12 checks/yr × 0.8 hours avg = 1,920h saved. CSRD audit penalty risk reduction = additional strategic value.
A39: 9 | B39: Invoice Processing & Anomaly Detection | C39: P2P | D39: Jaggaer (anomaly detection live) / SAP Joule (Q4 2025) | E39: 70% reduction in manual invoice processing time | F39: Invoices × time saved × FTE cost rate | G39: =B25*B24/60*B9/1750*0.7*0.4 | H39: =B25*B24/60*B9/1750*0.7 | I39: =B25*B24/60*B9/1750*0.7*1.5 | J39: High | K39: Jaggaer anomaly detection launched 2025; SAP Joule native | L39: 3 | M39: 4–6 wks | N39: B | O39: 0 | P39: 5000 | Q39: =H39-P39 | R39: =Q39*3-O39 | S39: =IF(O39+P39>0,H39/(O39+P39),"∞") | T39: 18,000 invoices × 15min × 70% saving × €68.57/hr = €121K. Plus fraud/error prevention value.
A40: 10 | B40: Market Intelligence Agent (Daily Briefings) | C40: Market Intel | D40: GEP (15% lower logistics costs) / Equinor commodity monitoring | E40: 1% better purchase timing on commodity-exposed spend (est. 30% of total) | F40: Commodity-exposed spend × price timing improvement | G40: =B7*0.3*0.01*0.4 | H40: =B7*0.3*0.01 | I40: =B7*0.3*0.01*2 | J40: Medium | K40: GEP/McKinsey benchmarked; Equinor live on commodity monitoring | L40: 2 | M40: 2–4 wks | N40: A/B | O40: 0 | P40: 3000 | Q40: =H40-P40 | R40: =Q40*3-O40 | S40: =IF(O40+P40>0,H40/(O40+P40),"∞") | T40: 30% of spend commodity-exposed = €150M. 1% better timing = €1.5M base. Conservative given steel/copper volatility 2024-25.
A41: 11 | B41: Should-Cost Modelling Agent | C41: Cost Intelligence | D41: McKinsey: 13% savings in raw-materials from should-cost AI | E41: 1% savings on addressable direct spend via better cost baselines | F41: Direct material spend × should-cost savings rate | G41: =B7*0.25*0.01*0.4 | H41: =B7*0.25*0.01 | I41: =B7*0.25*0.013 | J41: High | K41: McKinsey: 13% raw materials savings confirmed; Arkestro: 18.8% | L41: 6 | M41: 8–12 wks | N41: D | O41: 20000 | P41: 35000 | Q41: =H41-P41 | R41: =Q41*3-O41 | S41: =IF(O41+P41>0,H41/(O41+P41),"∞") | T41: 25% of spend = direct materials. 1% conservative savings (McKinsey 13%, using 1% for Statkraft first year).
A42: 12 | B42: Supplier Onboarding Automation | C42: Supplier Mgmt | D42: TealBook / Scoutbee (Coupa acquisition Oct 2025) | E42: 60% reduction in onboarding time (45 days → 18 days) | F42: Time saved × FTE cost + faster project start value | G42: =B9/250*B26*0.6*40*0.4 | H42: =B9/250*B26*0.6*40 | I42: =B9/250*B26*0.6*40*1.5 | J42: Medium | K42: TealBook/Scoutbee live; 60% onboarding time reduction typical | L42: 6 | M42: 10–14 wks | N42: C | O42: 10000 | P42: 15000 | Q42: =H42-P42 | R42: =Q42*3-O42 | S42: =IF(O42+P42>0,H42/(O42+P42),"∞") | T42: Assume 40 new suppliers/yr, 45 days → 18 days saved × €460/day FTE cost.
A43: 13 | B43: Tail Spend Automation Agent | C43: P2P | D43: Fairmarkit: $40K savings per buyer/week; 10x events per FTE | E43: 15% savings on tail spend (typically managed at sub-optimal prices) | F43: Tail spend × savings rate from competitive mini-tendering | G43: =B7*B23*0.15*0.4 | H43: =B7*B23*0.15 | I43: =B7*B23*0.15*1.8 | J43: High | K43: Fairmarkit live with documented $40K/buyer/week savings | L43: 4 | M43: 6–10 wks | N43: D | O43: 10000 | P43: 20000 | Q43: =H43-P43 | R43: =Q43*3-O43 | S43: =IF(O43+P43>0,H43/(O43+P43),"∞") | T43: Tail spend = 8% of €500M = €40M. 15% savings via competitive mini-tenders = €6M. Conservative vs Fairmarkit benchmarks.
A44: 14 | B44: Project Cost Intelligence Agent | C44: Decision Intel | D44: ScienceDirect (40% overrun avg) / McKinsey (80% on megaprojects) | E44: 2% improvement in estimate accuracy on capex spend | F44: Capex × overrun rate × % reduction from better cost intelligence | G44: =B20*B21*0.02*0.3 | H44: =B20*B21*0.02 | I44: =B20*B21*0.02*2 | J44: Medium | K44: ScienceDirect: 40% avg overrun (662 projects, $1.358T). Conservative 2% improvement. | L44: 10 | M44: 16–24 wks | N44: D | O44: 30000 | P44: 60000 | Q44: =H44-P44 | R44: =Q44*3-O44 | S44: =IF(O44+P44>0,H44/(O44+P44),"∞") | T44: €200M capex × 40% overrun rate × 2% improvement = €1.6M base. Mines SAP/Jaggaer actuals vs. estimates.
A45: 15 | B45: EPC Contract AI Review Agent | C45: Contract Mgmt | D45: Ironclad ($150M ARR, 39% growth) / Icertis (33 Fortune 100 clients) | E45: 40–60% legal cycle time reduction on complex contracts | F45: Legal/procurement hours saved on EPC contract review per year | G45: =B9/1750*20*B12*40*0.4*0.4 | H45: =B9/1750*20*B12*40*0.4 | I45: =B9/1750*20*B12*40*0.6 | J45: Medium | K45: Ironclad/Icertis live at Fortune 100; 40% cycle time reduction confirmed | L45: 8 | M45: 12–18 wks | N45: D | O45: 20000 | P45: 40000 | Q45: =H45-P45 | R45: =Q45*3-O45 | S45: =IF(O45+P45>0,H45/(O45+P45),"∞") | T45: 20 major EPC contracts/yr × avg 40 review hours × 40% savings. Plus risk reduction from catching non-standard clauses.
A46: 16 | B46: Supplier Risk Intelligence — Financial | C46: Risk Mgmt | D46: Resilinc (Gartner Magic Quadrant Leader) / Shell continuous monitoring | E46: 1 major supplier failure prevented per 2 years (€2M avg cost prevented) | F46: Probability-weighted cost of supplier failure events avoided | G46: =2000000/2*0.3 | H46: =2000000/2 | I46: =2000000/2*2 | J46: Medium | K46: Resilinc Gartner Leader; Shell financial monitoring live | L46: 6 | M46: 8–12 wks | N46: D | O46: 10000 | P46: 20000 | Q46: =H46-P46 | R46: =Q46*3-O46 | S46: =IF(O46+P46>0,H46/(O46+P46),"∞") | T46: €2M avg cost of unplanned supplier switch (emergency sourcing + project delay). 1 event prevented per 2 yrs conservative.
A47: 17 | B47: SAP Joule Activation (Native — Quick Win) | C47: Platform AI | D47: SAP: 30% productivity target; 14 new Joule agents Q4 2025 | E47: 20% productivity gain on SAP-native procurement tasks | F47: SAP users × time in SAP × productivity gain | G47: =B9/1750*1000*0.2*B9*0.4 | H47: =B9/1750*1000*0.2*B9 | I47: =B9/1750*1000*0.2*B9*1.5 | J47: High | K47: SAP native — no custom integration. Joule agents live Q4 2025 | L47: 1 | M47: 1–2 wks | N47: A | O47: 0 | P47: 0 | Q47: =H47-P47 | R47: =Q47*3-O47 | S47: =IF(O47+P47>0,H47/(O47+P47),"∞") | T47: Included in existing SAP licence. Bid analysis, SOW automation, NL demand routing, delivery date mass updates.
A48: 18 | B48: Jaggaer JAI Activation (Native) | C48: Platform AI | D48: Jaggaer JAI: Gartner score 3.75; copilot + anomaly detection live | E48: 15% efficiency gain on sourcing and contract tasks in Jaggaer | F48: Jaggaer users × time × efficiency gain | G48: =B9/1750*800*0.15*B9*0.4 | H48: =B9/1750*800*0.15*B9 | I48: =B9/1750*800*0.15*B9*1.5 | J48: High | K48: Native Jaggaer JAI — copilot live, agentic platform 2026 | L48: 1 | M48: 1–2 wks | N48: A | O48: 0 | P48: 0 | Q48: =H48-P48 | R48: =Q48*3-O48 | S48: =IF(O48+P48>0,H48/(O48+P48),"∞") | T48: Included in existing Jaggaer licence. JAI copilot, anomaly detection, conversational CLM live.
A49: 19 | B49: Autonomous Tender Management (Low Value) | C49: P2P | D49: Zip (50+ agents, $6B savings) / Pactum (<$150K autonomous negotiation) | E49: End-to-end automation of tenders <€50K | F49: Low-value tender volume × avg value × savings rate | G49: =B10*0.4*50000*0.08*0.4 | H49: =B10*0.4*50000*0.08 | I49: =B10*0.4*50000*0.08*1.5 | J49: Medium | K49: Zip and Pactum live at scale; 100 events automated per year est. | L49: 6 | M49: 10–16 wks | N49: D | O49: 15000 | P49: 30000 | Q49: =H49-P49 | R49: =Q49*3-O49 | S49: =IF(O49+P49>0,H49/(O49+P49),"∞") | T49: 40% of 250 events = 100 low-value. Avg €50K × 8% savings = €400K base. Pactum managing <$150K autonomously.
A50: 20 | B50: Supply Chain Network Risk Mapping | C50: Risk/Strategy | D50: GEP (15% lower logistics, 35% inventory) / Resilinc sub-tier mapping | E50: Risk-adjusted value: 1 major supply disruption prevented per year | F50: Probability × impact of supply disruption avoided | G50: =5000000*0.15*0.3 | H50: =5000000*0.15 | I50: =5000000*0.15*2 | J50: Low | K50: GEP/Resilinc benchmarks; supply disruption costs well documented | L50: 10 | M50: 16–24 wks | N50: D | O50: 25000 | P50: 50000 | Q50: =H50-P50 | R50: =Q50*3-O50 | S50: =IF(O50+P50>0,H50/(O50+P50),"∞") | T50: Major supply disruption (e.g. transformer shortage) costs €5M+ in project delay. 15% probability prevention.
A51: PROGRAMME TOTAL (all 20 use cases fully deployed) | G51: =SUM(G31:G50) | H51: =SUM(H31:H50) | I51: =SUM(I31:I50) | O51: =SUM(O31:O50) | P51: =SUM(P31:P50) | Q51: =SUM(Q31:Q50) | R51: =SUM(R31:R50) | S51: =H51/(O51+P51)
...

Sheet 🎯 Summary for Deck
A1: PROGRAMME VALUE SUMMARY — Numbers to Update in Presentation
A4: Metric | B4: Bear | C4: Base | D4: Bull | E4: Use in Deck
A5: Phase 0 Quick Wins (SAP Joule + Jaggaer JAI) | B5: ='📊 Use Case Value Register'!D55 | C5: ='📊 Use Case Value Register'!E55 | D5: ='📊 Use Case Value Register'!F55 | E5: Year 1 fast start
A6: Phase 1 Pilots (Spend, Contract, Supplier Monitor) | B6: ='📊 Use Case Value Register'!D56 | C6: ='📊 Use Case Value Register'!E56 | D6: ='📊 Use Case Value Register'!F56 | E6: 90-day review gate
A7: Phase 2 Expanded (6 use cases) | B7: ='📊 Use Case Value Register'!D57 | C7: ='📊 Use Case Value Register'!E57 | D7: ='📊 Use Case Value Register'!F57 | E7: Month 4-6 value
A8: Phase 3 Full Agentic (8 use cases) | B8: ='📊 Use Case Value Register'!D58 | C8: ='📊 Use Case Value Register'!E58 | D8: ='📊 Use Case Value Register'!F58 | E8: Month 7-12 value
A9: TOTAL ANNUAL VALUE — ALL 20 USE CASES | B9: ='📊 Use Case Value Register'!G51 | C9: ='📊 Use Case Value Register'!H51 | D9: ='📊 Use Case Value Register'!I51 | E9: Update Slide 10 TCO box
A10: Total Programme CAPEX | B10: ='📊 Use Case Value Register'!O51 | C10: ='📊 Use Case Value Register'!O51 | D10: ='📊 Use Case Value Register'!O51 | E10: Update hardware cost slide
A11: Total Annual OPEX | B11: ='📊 Use Case Value Register'!P51 | C11: ='📊 Use Case Value Register'!P51 | D11: ='📊 Use Case Value Register'!P51 | E11: Update TCO slide
A12: 3-Year NPV | B12: ='📊 Use Case Value Register'!R51 | C12: ='📊 Use Case Value Register'!R51 | D12: ='📊 Use Case Value Register'!R51 | E12: Update ROI box
A13: Programme ROI | B13: ='📊 Use Case Value Register'!S51 | C13: ='📊 Use Case Value Register'!S51 | D13: ='📊 Use Case Value Register'!S51 | E13: Update ROI box
